Workbook

Sheet START
B1: Software Engineer Transformation - Tracker
B2: Open this every day. It is the only file you need to know what to do.
B4: START DATE (a Monday) | C4: 46258
C5: Change that one yellow cell and every date in the whole workbook moves with it. It must be a Monday.
B7: HOW TO USE THIS
B8: 1. Every morning | C8: Open the DAILY tab. Press Ctrl+F, type today's date, and work that one row. That is the whole system.
B9: 2. Every evening | C9: Put an x in the Done column. Add anything you could not recall to the WEAK tab. Write one line in the JOURNAL tab.
B10: 3. Every Friday | C10: No new material. Work only the WEAK tab - the items with the oldest dates first.
B11: 4. Every Sunday | C11: Take the weekly test (6 tasks, listed below). Then read next week's row in the WEEKS tab.
B12: 5. Every month end | C12: Fill one column of the DASHBOARD tab. Three numbers. Nothing else.
B14: THE DAILY 2 HOURS
B15: 0:00 - 0:10 | C15: Explain yesterday out loud, notes closed. Badly is fine. NEVER skip this - it is the highest-leverage habit in the plan.
B16: 0:10 - 1:15 | C16: Today's topic, from the DAILY tab. Short notes only.
B17: 1:15 - 1:55 | C17: DSA. One or two problems. Log all six fields in the DSA tab.
B18: 1:55 - 2:00 | C18: Weak List, journal line, tomorrow's one-line plan.
B19: Tue and Thu | C19: Add 15 minutes of aptitude at the end. That is the only variation.
B21: THE SUNDAY TEST - 6 tasks, no notes
C22: Explain 5 concepts from this week aloud, recorded
C23: Solve 2 DSA problems, 25 minutes each
C24: Talk through 1 system design for 10-15 min (from week 12)
C25: Implement 1 small C# example from memory, no IDE help
C26: Speak 2 minutes in English on one technical topic
C27: Write down 3 things you forgot - they go straight to the WEAK tab
B29: IF YOU FALL BEHIND
B30: Missed 2-3 days | C30: Ignore it. Carry on from today. Do NOT try to catch up.
B31: Missed a week | C31: Skip to the current week. Put the missed topics in the WEAK tab.
B32: Missed two weeks | C32: Same, and move the START DATE cell forward two weeks.
B33: Missed a month | C33: Restart the current month only. Never restart the plan.
B34: Too tired today | C34: The 30-minute version: 10 min recall + 15 min one DSA problem + 5 min journal. Never zero.
B36: WHAT THE TABS ARE FOR
B37: DAILY | C37: All 224 days. One row per day. This is the tab you live in.
B38: WEEKS | C38: The 32-week overview. Read one row every Sunday.
B39: WEAK | C39: Everything you got wrong. Drives every Friday. THE most important tab.
B40: DSA | C40: One row per problem, six fields. The log is where pattern recognition is built.
B41: REVIEW | C41: The 1/3/7/14/30-day ladder. Type the date you learned it; the rest calculates.
B42: DESIGNS | C42: All 18 system designs and 5 LLDs, with the week each is due.
B43: STORIES | C43: Your 20 STAR stories mapped to Amazon's 16 principles. No column may be empty.
B44: JOURNAL | C44: One line per working day. This becomes your 20 stories in month 5.
B45: APPLY | C45: Every application, with the sponsor-register and LinkedIn checks.
B46: INTERVIEWS | C46: Every interview, with a named ROOT CAUSE and a repair date.
...

Sheet DAILY
A1: Date | B1: Day | C1: Wk | D1: Mth | E1: TODAY'S TOPIC | F1: ALSO DO | G1: MUST BE ABLE TO EXPLAIN | H1: Done
A2: =START!$C$4 -> 46258 | B2: Mon | C2: 1 | D2: M1 | E2: Value vs reference types. Stack vs heap. What a variable actually holds. Assignment and copy semantics | F2: DSA: Big-O, time vs space. Write a demo where copying a struct and copying a class differ | G2: Why passing a struct to a method may not change the original
A3: =A2+1 -> 46259 | B3: Tue | C3: 1 | D3: M1 | E3: struct vs class. Boxing and unboxing. Nullable value types. Where structs actually live | F3: DSA: arrays. Use SharpLab to watch the IL box instruction appear. + 15 min aptitude | G3: What boxing costs and three places it happens accidentally
A4: =A3+1 -> 46260 | B4: Wed | C4: 1 | D4: M1 | E4: Strings: immutability, interning, StringBuilder, why concat in a loop is O(n squared) | F4: DSA. Benchmark string concat vs StringBuilder over 100k iterations | G4: Why strings are immutable and what that buys you
A5: =A4+1 -> 46261 | B5: Thu | C5: 1 | D5: M1 | E5: ref, out, in parameters. Pass by value vs by reference for both type categories. readonly, const, static | F5: DSA. Write the four-case matrix and predict each result before running. + 15 min aptitude | G5: The difference between a reference type and passing by reference
A6: =A5+1 -> 46262 | B6: Fri | C6: 1 | D6: M1 | E6: No new material. Weak List only. Explain the whole week aloud, recorded | F6: Re-solve every DSA problem you needed help with | G6: Everything from this week, cold, no notes
A7: =A6+1 -> 46263 | B7: Sat | C7: 1 | D7: M1 | E7: DEEP: object layout in memory, object header, method table pointer, why a reference costs 8 bytes on x64. GC generations intro | F7: Read Book of the Runtime intro. Draw the heap layout by hand | G7: What is physically in memory when you write new Person()
A8: =A7+1 -> 46264 | B8: Sun | C8: 1 | D8: M1 | E8: WEEKLY TEST, no notes. Then plan week 2 | F8: Record a 2-minute explanation of stack vs heap | G8: Write down 3 things you forgot - they go on the Weak List
A9: =A8+1 -> 46265 | B9: Mon | C9: 2 | D9: M1 | E9: Classes, constructors, constructor chaining, object initialisers, access modifiers, static members and static constructor timing | F9: DSA: hash tables. Write a class with three chained constructors; predict init order first | G9: When a static constructor actually runs
A10: =A9+1 -> 46266 | B10: Tue | C10: 2 | D10: M1 | E10: Inheritance. virtual, override, new (shadowing), abstract, sealed. Virtual dispatch and the method table | F10: DSA. Demo where new vs override differ through a base reference. + 15 min aptitude | G10: How the runtime picks which method to call, at method-table level
A11: =A10+1 -> 46267 | B11: Wed | C11: 2 | D11: M1 | E11: Interfaces. Explicit implementation. Default interface methods. Interface vs abstract class - the real criteria | F11: DSA. Implement IComparable<T> and IEquatable<T> on your own type | G11: When to choose an interface over an abstract class, with a concrete reason
A12: =A11+1 -> 46268 | B12: Thu | C12: 2 | D12: M1 | E12: Composition over inheritance. Encapsulation. Equals, GetHashCode, ToString. The Equals/GetHashCode contract | F12: DSA. Override both, then break the contract and watch a Dictionary lose your key. + aptitude | G12: Why breaking that contract corrupts hash-based collections
A13: =A12+1 -> 46269 | B13: Fri | C13: 2 | D13: M1 | E13: No new material. Weak List only. Explain the whole week aloud, recorded | F13: Re-solve every DSA problem you needed help with | G13: Everything from this week, cold, no notes
A14: =A13+1 -> 46270 | B14: Sat | C14: 2 | D14: M1 | E14: DEEP: polymorphism internals, covariance and contravariance (in/out), generic constraints, why .NET generics are not Java erasure | F14: Write a generic repository with constraints. Inspect the JIT-specialised code | G14: Why List<int> and List<string> are genuinely different types at runtime
... A225: =A224+1 -> 46481 | B225: Sun | C225: 32 | D225: M8 | E225: FINAL CUMULATIVE TEST. Then plan what comes next - more interviews, or the first 90 days of a new job | F225: Run the final checkpoint list | G225: What you can do from memory, under time pressure, in English

Sheet WEEKS
A1: Wk | B1: Mth | C1: Starts | D1: Ends | E1: THIS WEEK IS ABOUT | F1: DSA THEME | G1: DONE BY SUNDAY | H1: OK?
A2: 1 | B2: M1 | C2: =START!$C$4+0 -> 46258 | D2: =C2+6 -> 46264 | E2: The type system and memory | F2: Big-O and arrays | G2: 10 problems logged. First Sunday test done
A3: 2 | B3: M1 | C3: =START!$C$4+7 -> 46265 | D3: =C3+6 -> 46271 | E3: Object orientation, properly | F3: Strings and hashing | G3: 10 problems. Weak List growing. Toy comparisons built
A4: 3 | B4: M1 | C4: =START!$C$4+14 -> 46272 | D4: =C4+6 -> 46278 | E4: Collections, LINQ, delegates | F4: Two pointers and sliding window | G4: 10 problems. Toy hash map built
A5: 4 | B5: M1 | C5: =START!$C$4+21 -> 46279 | D5: =C5+6 -> 46285 | E5: Exceptions, lifetime, and async - the most important week of M1 | F5: Stack, queue, binary search | G5: Month 1 checkpoint passed. ~40 problems total
A6: 5 | B6: M2 | C6: =START!$C$4+28 -> 46286 | D6: =C6+6 -> 46292 | E6: Concurrency and parallelism | F6: Linked lists | G6: Producer-consumer built. 10 problems
A7: 6 | B7: M2 | C7: =START!$C$4+35 -> 46293 | D7: =C7+6 -> 46299 | E7: The runtime and the ASP.NET Core platform | F7: Recursion | G7: Minimal API built from an empty project. AI answer drafted
A8: 7 | B8: M2 | C8: =START!$C$4+42 -> 46300 | D8: =C8+6 -> 46306 | E8: Web API, security, and EF Core | F8: Trees and BST | G8: N+1 reproduced and fixed. Redis cache-aside working
A9: 8 | B9: M2 | C9: =START!$C$4+49 -> 46307 | D9: =C9+6 -> 46313 | E9: SQL and database internals - highest immediate job value in the plan | F9: Heaps and priority queues. FIRST TIMED SESSIONS | G9: Month 2 checkpoint. Dirty read and deadlock reproduced
A10: 9 | B10: M3 | C10: =START!$C$4+56 -> 46314 | D10: =C10+6 -> 46320 | E10: Networking | F10: Graphs part 1 - BFS and DFS | G10: Full URL journey explained aloud
A11: 10 | B11: M3 | C11: =START!$C$4+63 -> 46321 | D11: =C11+6 -> 46327 | E11: Operating systems | F11: Graphs part 2 - topological sort and union-find | G11: 10 problems. Two-layer scheduler diagram drawn
A12: 11 | B12: M3 | C12: =START!$C$4+70 -> 46328 | D12: =C12+6 -> 46334 | E12: Distributed data and caching | F12: Intervals and greedy | G12: Consistent hashing implemented. Unfamiliar codebase read cold
A13: 12 | B13: M3 | C13: =START!$C$4+77 -> 46335 | D13: =C13+6 -> 46341 | E13: Messaging, and SYSTEM DESIGN BEGINS | F13: Mixed set - interleaving starts | G13: Month 3 checkpoint. 3 designs timed. Mixed DSA sets begin
A14: 13 | B14: M4 | C14: =START!$C$4+84 -> 46342 | D14: =C14+6 -> 46348 | E14: SOLID and object-oriented design | F14: Backtracking | G14: 3 LLDs done from a blank page
A15: 14 | B15: M4 | C15: =START!$C$4+91 -> 46349 | D15: =C15+6 -> 46355 | E15: Design patterns - only the ones that matter | F15: Dynamic programming part 1 | G15: Caching decorator built. 2 more LLDs
A16: 15 | B16: M4 | C16: =START!$C$4+98 -> 46356 | D16: =C16+6 -> 46362 | E16: Distributed systems - the hard parts | F16: Mixed medium set | G16: READ DOC 10 THIS WEEK. Project designed before it is built
A17: 16 | B17: M4 | C17: =START!$C$4+105 -> 46363 | D17: =C17+6 -> 46369 | E17: PROJECT PHASE 1 - the walking skeleton | F17: Mixed medium set | G17: Month 4 checkpoint. Project runs end to end
A18: 17 | B18: M5 | C18: =START!$C$4+112 -> 46370 | D18: =C18+6 -> 46376 | E18: PROJECT PHASE 2 - reliability | F18: Dynamic programming part 2 | G18: Phase 2 done. 5 STAR stories written
A19: 18 | B19: M5 | C19: =START!$C$4+119 -> 46377 | D19: =C19+6 -> 46383 | E19: PROJECT PHASE 3 - production concerns | F19: Mixed medium set, all timed | G19: Phase 3 done. Dashboard live. 10 stories total
A20: 19 | B20: M5 | C20: =START!$C$4+126 -> 46384 | D20: =C20+6 -> 46390 | E20: PROJECT PHASE 4 - ship it | F20: Mixed medium set | G20: Project DEPLOYED with real p95/p99 numbers. 15 stories total
A21: 20 | B21: M5 | C21: =START!$C$4+133 -> 46391 | D21: =C21+6 -> 46397 | E21: System design depth and behavioural - THE GATE TO APPLYING | F21: Mixed medium set + full Weak List re-solve | G21: MONTH 5 CHECKPOINT - the gate. All 20 stories recorded
A22: 21 | B22: M6 | C22: =START!$C$4+140 -> 46398 | D22: =C22+6 -> 46404 | E22: APPLICATIONS LAUNCH - calibration week | F22: Timed DSA, 2 medium/day | G22: Pipeline live. Applications tracked in the APPLY tab
A23: 22 | B23: M6 | C23: =START!$C$4+147 -> 46405 | D23: =C23+6 -> 46411 | E23: Volume and calibration | F23: Timed DSA + 2 external mocks | G23: 2 external mocks done. Tier 1 applications out
A24: 23 | B24: M6 | C24: =START!$C$4+154 -> 46412 | D24: =C24+6 -> 46418 | E24: AMAZON WEEK - preparation | F24: Amazon-tagged DSA | G24: Amazon application in. Full LP matrix complete
A25: 24 | B25: M6 | C25: =START!$C$4+161 -> 46419 | D25: =C25+6 -> 46425 | E25: GOOGLE WEEK - preparation | F25: Google-tagged DSA, NO IDE all week | G25: Month 6 checkpoint. Google application in
A26: 25 | B26: M7 | C26: =START!$C$4+168 -> 46426 | D26: =C26+6 -> 46432 | E26: Gap repair and advanced messaging | F26: Timed DSA 2 medium | G26: 1 gap closed. RAG skeleton built
A27: 26 | B27: M7 | C27: =START!$C$4+175 -> 46433 | D27: =C27+6 -> 46439 | E27: Reliability, scale and the deeper design questions | F27: Timed DSA | G27: Vector search working. Another gap closed
A28: 27 | B28: M7 | C28: =START!$C$4+182 -> 46440 | D28: =C28+6 -> 46446 | E28: Company-specific depth | F28: Amazon- and Google-tagged sets | G28: 3 weakest stories re-recorded. RAG generating with citations
A29: 28 | B29: M7 | C29: =START!$C$4+189 -> 46447 | D29: =C29+6 -> 46453 | E29: Consolidation and the hard round | F29: Selected hard DSA, patterns you own | G29: Month 7 checkpoint. RAG deployed with measured numbers
A30: 29 | B30: M8 | C30: =START!$C$4+196 -> 46454 | D30: =C30+6 -> 46460 | E30: Retrieval intensive | F30: Re-solve every missed problem from memory | G30: One-page pattern sheet written by you
A31: 30 | B31: M8 | C31: =START!$C$4+203 -> 46461 | D31: =C31+6 -> 46467 | E31: Oral revision and design volume | F31: Timed DSA maintenance | G31: 45-minute monologues recorded across all areas
A32: 31 | B32: M8 | C32: =START!$C$4+210 -> 46468 | D32: =C32+6 -> 46474 | E32: Peak simulation | F32: Hard DSA in patterns you own | G32: Onsite fatigue simulated. Both projects defended
A33: 32 | B33: M8 | C33: =START!$C$4+217 -> 46475 | D33: =C33+6 -> 46481 | E33: CONVERSION - offers and negotiation | F33: Light DSA maintenance only | G33: Final checkpoint. A number you can state calmly

Sheet WEAK
A1: What I could not recall / explain / solve | B1: Added | C1: Where from | D1: Try 1 | E1: Try 2 | F1: Cleared | G1: Note
A2: Why .Result deadlocks | C2: Weekly test | D2: fail | E2: pass | G2: EXAMPLE ROW - delete it

Sheet DSA
A1: Problem | B1: E/M/H | C1: Pattern | D1: Brute O | E1: Opt O | F1: Key insight (ONE sentence) | G1: One variation | H1: Re-solve 1/3/7/14
A2: Two Sum | B2: E | C2: Hashing | D2: O(n^2) | E2: O(n) | F2: Complement lookup in a map | G2: If sorted, two pointers | H2: EXAMPLE - delete

Sheet REVIEW
A1: Concept | B1: Learned on | C1: Day 1 | D1: Day 3 | E1: Day 7 | F1: Day 14 | G1: Day 30 | H1: Pass / fail (fail = back to Day 1)
C2: =IF($B2="","",$B2+1) | D2: =IF($B2="","",$B2+3) | E2: =IF($B2="","",$B2+7) | F2: =IF($B2="","",$B2+14) | G2: =IF($B2="","",$B2+30)
C3: =IF($B3="","",$B3+1) | D3: =IF($B3="","",$B3+3) | E3: =IF($B3="","",$B3+7) | F3: =IF($B3="","",$B3+14) | G3: =IF($B3="","",$B3+30)
C4: =IF($B4="","",$B4+1) | D4: =IF($B4="","",$B4+3) | E4: =IF($B4="","",$B4+7) | F4: =IF($B4="","",$B4+14) | G4: =IF($B4="","",$B4+30)
C5: =IF($B5="","",$B5+1) | D5: =IF($B5="","",$B5+3) | E5: =IF($B5="","",$B5+7) | F5: =IF($B5="","",$B5+14) | G5: =IF($B5="","",$B5+30)
C6: =IF($B6="","",$B6+1) | D6: =IF($B6="","",$B6+3) | E6: =IF($B6="","",$B6+7) | F6: =IF($B6="","",$B6+14) | G6: =IF($B6="","",$B6+30)
C7: =IF($B7="","",$B7+1) | D7: =IF($B7="","",$B7+3) | E7: =IF($B7="","",$B7+7) | F7: =IF($B7="","",$B7+14) | G7: =IF($B7="","",$B7+30)
C8: =IF($B8="","",$B8+1) | D8: =IF($B8="","",$B8+3) | E8: =IF($B8="","",$B8+7) | F8: =IF($B8="","",$B8+14) | G8: =IF($B8="","",$B8+30)
C9: =IF($B9="","",$B9+1) | D9: =IF($B9="","",$B9+3) | E9: =IF($B9="","",$B9+7) | F9: =IF($B9="","",$B9+14) | G9: =IF($B9="","",$B9+30)
C10: =IF($B10="","",$B10+1) | D10: =IF($B10="","",$B10+3) | E10: =IF($B10="","",$B10+7) | F10: =IF($B10="","",$B10+14) | G10: =IF($B10="","",$B10+30)
C11: =IF($B11="","",$B11+1) | D11: =IF($B11="","",$B11+3) | E11: =IF($B11="","",$B11+7) | F11: =IF($B11="","",$B11+14) | G11: =IF($B11="","",$B11+30)
C12: =IF($B12="","",$B12+1) | D12: =IF($B12="","",$B12+3) | E12: =IF($B12="","",$B12+7) | F12: =IF($B12="","",$B12+14) | G12: =IF($B12="","",$B12+30)
C13: =IF($B13="","",$B13+1) | D13: =IF($B13="","",$B13+3) | E13: =IF($B13="","",$B13+7) | F13: =IF($B13="","",$B13+14) | G13: =IF($B13="","",$B13+30)
... C201: =IF($B201="","",$B201+1) | D201: =IF($B201="","",$B201+3) | E201: =IF($B201="","",$B201+7) | F201: =IF($B201="","",$B201+14) | G201: =IF($B201="","",$B201+30)

Sheet DESIGNS
A1: # | B1: Design | C1: Due week | D1: Date done | E1: Minutes | F1: The trade-off I named out loud | G1: Done
A2: SD 1 | B2: URL shortener | C2: 12
A3: SD 2 | B3: Rate limiter | C3: 12
A4: SD 3 | B4: Notification service | C4: 12
A5: SD 4 | B5: Distributed job queue (your project) | C5: 15
A6: SD 5 | B6: File storage (Dropbox) | C6: 15
A7: SD 6 | B7: News feed (Twitter/Instagram) | C7: 20
A8: SD 7 | B8: Ecommerce order processing | C8: 20
A9: SD 8 | B9: Payment workflow | C9: 20
A10: SD 9 | B10: Chat system (WhatsApp) | C10: 20
A11: SD 10 | B11: Web crawler | C11: 21
A12: SD 11 | B12: Video platform (YouTube) | C12: 22
A13: SD 12 | B13: Typeahead / autocomplete | C13: 22
... A28: REDO | B28: Re-do 3 more designs from scratch | C28: 31

Sheet STORIES
A1: Story (one per row - target 20) | B1: Written | C1: Recorded | D1: Customer Obsession* | E1: Ownership* | F1: Invent & Simplify | G1: Are Right A Lot | H1: Learn & Be Curious | I1: Hire & Develop | J1: Highest Standards | K1: Think Big | L1: Bias for Action* | M1: Frugality | N1: Earn Trust* | O1: Dive Deep* | P1: Have Backbone* | Q1: Deliver Results* | R1: Best Employer | S1: Broad Responsibility
A2: Email pipeline 7-10h to 1.5h (~80%) - FLAGSHIP
A3: FOIA backend features for US federal agencies
A4: Legacy refactoring / platform modernisation
A5: SQL optimisation on large eDiscovery datasets
A6: Multilingual content processing
A7: 100k+ record datasets at Zibma
A8: Payment gateways - Stripe, PayPal, CCAvenue
A9: Vonage video integration (VCDoctor)
A10: SignalR messaging + FCM multi-device signalling
A11: ERP reporting for multiple institutions
A12: .NET Core APIs into an existing ASP.NET app
A13: Hardest production incident I resolved
... A27: * = appears in roughly 85% of Amazon interviews. EVERY column needs at least two marks. A column with zero marks is an interview you are going to lose.

Sheet JOURNAL
A1: Date | B1: One line: what problem came up, what I decided, what happened | C1: Story material?
B2: Bulk export timing out at 50k records. Chose to batch and stream rather than raise the timeout. Cut memory use, export finished in 4 min. <- EXAMPLE, delete it | C2: yes

Sheet APPLY
A1: Company | B1: Country | C1: Route | D1: Doc 14 tier | E1: On sponsor register? | F1: LinkedIn test | G1: Applied | H1: Referral | I1: Stage | J1: Next action | K1: By when
A2: Thomson Reuters | B2: Canada | C2: Direct + Transfer | D2: 3A
A3: OpenText | B3: Canada | C3: Direct + Transfer | D3: 3A
A4: Magnet Forensics | B4: Canada | C4: Direct | D4: 3A
A5: Constellation Software | B5: Canada | C5: Direct | D5: 3A
A6: Xero | B6: New Zealand | C6: Direct | D6: 3B
A7: Datacom | B7: New Zealand | C7: Direct | D7: 3B
A8: Nuix | B8: Australia | C8: Direct | D8: 3C
A9: Objective Corporation | B9: Australia | C9: Direct | D9: 3C
A10: WiseTech Global | B10: Australia | C10: Direct | D10: 3C
A11: Microsoft Dublin | B11: Ireland | C11: Direct + Transfer | D11: 3E
A12: Fidelity Investments | B12: Ireland | C12: Direct + Transfer | D12: 3E
A13: Version 1 | B13: Ireland | C13: Direct + Transfer | D13: 3E
... A18: Casepoint US (L-1) | B18: US | C18: Transfer | D18: 3K

Sheet INTERVIEWS
A1: Company | B1: Round | C1: Date | D1: Result | E1: What went badly (the exact moment) | F1: ROOT CAUSE - the only column that matters | G1: Repair action | H1: Scheduled for
A2: (example) | B2: DSA | D2: Rejected | E2: Stalled 20 min on the approach | F2: Did not recognise it as a monotonic stack problem | G2: Re-drill monotonic stack
A154: "I failed the DSA round" is not a root cause. "I did not recognise the pattern and burned 20 minutes on brute force" is - and it has a repair. Vague post-mortems are why people interview for a year without improving.

Sheet DASHBOARD
A1: Update once a month. These are the only numbers worth tracking. | B1: M1 | C1: M2 | D1: M3 | E1: M4 | F1: M5 | G1: M6 | H1: M7 | I1: M8
A2: THE THREE THAT MATTER
A3: Days studied this month (out of available days)
A4: Weak List items cleared
A5: Concepts that passed the Day 30 review
A6: EVERYTHING ELSE
A7: DSA problems solved (logged, all six fields)
A8: Problems re-solved from memory
A9: System designs completed, timed
A10: LLDs completed, timed
A11: STAR stories written and rehearsed
A12: Mock interviews done
A13: Real interviews done
... A17: Not on this list, on purpose: hours studied, videos watched, pages read, tutorials finished. Those measure input. Every row above measures output, which is the only thing an interview can observe.
