Workbook

Sheet START
A1: Preparation tracker | B1: One workbook for the whole plan. Fill it in daily; it takes about 5 minutes.
A3: How dates work | B3: Change the START DATE below to the Monday you start. Every date in DAILY moves with it.
A4: START DATE (a Monday) | B4: 46321
A6: DAILY | B6: One row per day (224). Status: Not started / In progress / Done / Needs review / Deferred. 'Done' only when the day's 'Done when' is true.
A7: DSA_LOG | B7: Every planned problem, pre-filled. Fill Result, the date and the six fields. Re-solve dates calculate themselves (D+1, 3, 7, 14).
A8: REVIEW | B8: Every 'explain aloud' question, pre-filled. Enter the date you learned it; review dates calculate (D+1, 3, 7, 14, 30).
A9: WEAK | B9: Anything you could not explain or solve. Exit rule: two successful recalls at least 7 days apart.
A10: DESIGNS | B10: Every HLD and LLD with its planned day. Score yourself out of 20 with the practice rubric.
A11: STORIES | B11: Your real stories mapped to the 16 Amazon Leadership Principles. Never invent; leave unknown numbers blank.
A12: JOURNAL | B12: One line per working day: problem, decision, outcome. This becomes your story bank.
A13: PROJECT | B13: Milestones M1–M12 with acceptance tests.
A14: APPLY / INTERVIEWS | B14: Applications from Week 21; an analysis within 24 hours of every interview.
A15: DASHBOARD | B15: Counts that update themselves.

Sheet DAILY
A1: Day | B1: Date | C1: Weekday | D1: Week | E1: Phase | F1: Focus | G1: DSA problems | H1: Core / rotating topic | I1: Explain aloud | J1: Status | K1: Minutes | L1: Recall | M1: Week file | N1: Notes
A2: 1 | B2: =START!$B$4+A2-1 | C2: =TEXT(B2,"ddd") | D2: 1 | E2: Foundations | F2: Array representation and traversal | G2: Array basics: print, sum, max, min, count of a target (handle empty input) | H2: C# program basics: a console project, variables and built-in types, arrays and Length | I2: Why is reading a[i] O(1) but finding a value O(n)? | J2: Not started | M2: =HYPERLINK("WEEKS/WEEK_01.md","Week 1 · Day 1")
A3: 2 | B3: =START!$B$4+A3-1 | C3: =TEXT(B3,"ddd") | D3: 1 | E3: Foundations | F3: Indexes, linear search and operation costs | G3: Linear search, first/last occurrence, minimum/maximum with index | H3: int vs long, integer division, overflow, checked arithmetic and conversions | I3: What is overflow and when should a sum use long? | J3: Not started | M3: =HYPERLINK("WEEKS/WEEK_01.md","Week 1 · Day 2")
A4: 3 | B4: =START!$B$4+A4-1 | C4: =TEXT(B4,"ddd") | D4: 1 | E4: Foundations | F4: Swapping and reversing in place | G4: Reverse an array in place with two indexes (0, 1, odd, even lengths) | H4: Methods, parameters, return values; value types vs reference types | I4: What does a variable of a value type hold, and what does a reference-type variable hold? | J4: Not started | M4: =HYPERLINK("WEEKS/WEEK_01.md","Week 1 · Day 3")
A5: 4 | B5: =START!$B$4+A5-1 | C5: =TEXT(B5,"ddd") | D5: 1 | E5: Foundations | F5: Sorted check and second-largest distinct | G5: Check sorted order; second-largest DISTINCT value | H5: Stack vs heap, where structs actually live, null vs empty, alias vs copy | I5: Where does a struct live — the stack or the heap? (It depends on where it is declared.) | J5: Not started | M5: =HYPERLINK("WEEKS/WEEK_01.md","Week 1 · Day 4")
A6: 5 | B6: =START!$B$4+A6-1 | C6: =TEXT(B6,"ddd") | D6: 1 | E6: Foundations | F6: Repair and retrieval | G6: re-solves + Concatenation of Array | H6: re-explain the week | J6: Not started | M6: =HYPERLINK("WEEKS/WEEK_01.md","Week 1 · Day 5")
A7: 6 | B7: =START!$B$4+A7-1 | C7: =TEXT(B7,"ddd") | D7: 1 | E7: Foundations | F7: Deep work: DSA + design + lab/project | G7: Insert / delete at an index by shifting, with spare capacity, Contains Duplicate | H7: How a web request works, on paper: client → DNS → server → API → database → response. Draw it. No scaling yet. | J7: Not started | M7: =HYPERLINK("WEEKS/WEEK_01.md","Week 1 · Day 6")
A8: 7 | B8: =START!$B$4+A8-1 | C8: =TEXT(B8,"ddd") | D8: 1 | E8: Foundations | F8: Weekly test, review, project, stories | H8: Predict-then-run lab: write 6 small C# examples about assignment and parameters (int, struct, class, array, string, ref) | J8: Not started | M8: =HYPERLINK("WEEKS/WEEK_01.md","Week 1 · Day 7")
A9: 8 | B9: =START!$B$4+A9-1 | C9: =TEXT(B9,"ddd") | D9: 2 | E9: Foundations | F9: Set membership and duplicate detection | G9: Contains Duplicate, Frequency map of an int[] with Dictionary (TryGetValue) | H9: Struct vs class, boxing and its hidden cost, nullable value types | I9: What is boxing, what does it cost, and name three places it happens by accident. | J9: Not started | M9: =HYPERLINK("WEEKS/WEEK_02.md","Week 2 · Day 8")
A10: 9 | B10: =START!$B$4+A10-1 | C10: =TEXT(B10,"ddd") | D10: 2 | E10: Foundations | F10: Two Sum, brute force first | G10: Two Sum | H10: Equality: ==, Equals, GetHashCode, IEquatable<T>, records | I10: State the Equals/GetHashCode contract and what breaks without it. | J10: Not started | M10: =HYPERLINK("WEEKS/WEEK_02.md","Week 2 · Day 9")
A11: 10 | B11: =START!$B$4+A11-1 | C11: =TEXT(B11,"ddd") | D11: 2 | E11: Foundations | F11: Two Sum in one pass with a map | G11: Two Sum, Longest Consecutive Sequence | H11: List<T>, Dictionary and HashSet internals: growth, buckets, collisions | I11: Why is Dictionary lookup O(1) on average, and what makes it O(n)? | J11: Not started | M11: =HYPERLINK("WEEKS/WEEK_02.md","Week 2 · Day 10")
A12: 11 | B12: =START!$B$4+A12-1 | C12: =TEXT(B12,"ddd") | D12: 2 | E12: Foundations | F12: Reader and writer pointers | G12: Move Zeroes, Remove Element | H12: ref, out, in; const vs readonly vs static; static constructors; object memory layout | I12: Explain ref, out and in in one sentence each. | J12: Not started | M12: =HYPERLINK("WEEKS/WEEK_02.md","Week 2 · Day 11")
A13: 12 | B13: =START!$B$4+A13-1 | C13: =TEXT(B13,"ddd") | D13: 2 | E13: Foundations | F13: Repair and retrieval | G13: re-solves + Find All Numbers Disappeared in an Array | H13: re-explain the week | J13: Not started | M13: =HYPERLINK("WEEKS/WEEK_02.md","Week 2 · Day 12")
A14: 13 | B14: =START!$B$4+A14-1 | C14: =TEXT(B14,"ddd") | D14: 2 | E14: Foundations | F14: Deep work: DSA + design + lab/project | G14: Remove Duplicates from Sorted Array, Running Sum of 1d Array, Plus One, Merge Sorted Array, Range Sum Query - Immutable | H14: API contract on paper: POST /jobs and GET /jobs/{id} — inputs, validation, status codes, stored fields. No code. | J14: Not started | M14: =HYPERLINK("WEEKS/WEEK_02.md","Week 2 · Day 13")
A15: 14 | B15: =START!$B$4+A15-1 | C15: =TEXT(B15,"ddd") | D15: 2 | E15: Foundations | F15: Weekly test, review, project, stories | H15: Re-solve Two Sum cold. Then explain Range Sum Query (303) from Saturday: derive prefix[r+1] − prefix[l] on paper, includ | J15: Not started | M15: =HYPERLINK("WEEKS/WEEK_02.md","Week 2 · Day 14")
A16: 15 | B16: =START!$B$4+A16-1 | C16: =TEXT(B16,"ddd") | D16: 3 | E16: Foundations | F16: String traversal and frequency | G16: Valid Anagram, Ransom Note | H16: Strings: immutability, interning, StringBuilder, why concatenation in a loop is O(n²) | I16: Why is string concatenation in a loop O(n²)? | J16: Not started | M16: =HYPERLINK("WEEKS/WEEK_03.md","Week 3 · Day 15")
A17: 16 | B17: =START!$B$4+A17-1 | C17: =TEXT(B17,"ddd") | D17: 3 | E17: Foundations | F17: Opposite-end pointers | G17: Valid Palindrome, Valid Palindrome II | H17: Classes, constructors and chaining, fields vs properties, the six access modifiers | I17: What is the job of a constructor? | J17: Not started | M17: =HYPERLINK("WEEKS/WEEK_03.md","Week 3 · Day 16")
A18: 17 | B18: =START!$B$4+A18-1 | C18: =TEXT(B18,"ddd") | D18: 3 | E18: Foundations | F18: Pointers on sorted input | G18: Two Sum II - Input Array Is Sorted, Squares of a Sorted Array | H18: virtual / override / new; interface vs abstract class | I18: Interface or abstract class — how do you decide? | J18: Not started | M18: =HYPERLINK("WEEKS/WEEK_03.md","Week 3 · Day 17")
A19: 18 | B19: =START!$B$4+A19-1 | C19: =TEXT(B19,"ddd") | D19: 3 | E19: Foundations | F19: Fixed-size windows | G19: Maximum Average Subarray I, Longest Common Prefix | H19: Composition over inheritance; generics, constraints and variance; generics vs Java erasure | I19: Why composition over inheritance? | J19: Not started | M19: =HYPERLINK("WEEKS/WEEK_03.md","Week 3 · Day 18")
A20: 19 | B20: =START!$B$4+A20-1 | C20: =TEXT(B20,"ddd") | D20: 3 | E20: Foundations | F20: Repair and retrieval | G20: re-solves + Reverse String | H20: re-explain the week | J20: Not started | M20: =HYPERLINK("WEEKS/WEEK_03.md","Week 3 · Day 19")
A21: 20 | B21: =START!$B$4+A21-1 | C21: =TEXT(B21,"ddd") | D21: 3 | E21: Foundations | F21: Deep work: DSA + design + lab/project | G21: First Unique Character in a String, Isomorphic Strings, Word Pattern, 3Sum | H21: URL shortener — requirements only: 3 functional requirements, 3 constraints, the redirect API. Single server. Read the c | J21: Not started | M21: =HYPERLINK("WEEKS/WEEK_03.md","Week 3 · Day 20")
A22: 21 | B22: =START!$B$4+A22-1 | C22: =TEXT(B22,"ddd") | D22: 3 | E22: Foundations | F22: Weekly test, review, project, stories | H22: Implement IComparable<T> and IEquatable<T> on a Money record; sort a list of jobs by priority with a custom IComparer. | J22: Not started | M22: =HYPERLINK("WEEKS/WEEK_03.md","Week 3 · Day 21")
A23: 22 | B23: =START!$B$4+A23-1 | C23: =TEXT(B23,"ddd") | D23: 4 | E23: Foundations | F23: Window validity and shrink rules | G23: Longest Substring Without Repeating Characters | H23: IEnumerable vs ICollection vs IList vs IQueryable; what yield return compiles into | I23: IEnumerable vs IQueryable — why does it matter for a database query? | J23: Not started | M23: =HYPERLINK("WEEKS/WEEK_04.md","Week 4 · Day 22")
A24: 23 | B24: =START!$B$4+A24-1 | C24: =TEXT(B24,"ddd") | D24: 4 | E24: Foundations | F24: Monotone windows and their limits | G24: Minimum Size Subarray Sum, Max Consecutive Ones III | H24: Deferred execution and LINQ costs | I24: What is deferred execution and give one bug it causes. | J24: Not started | M24: =HYPERLINK("WEEKS/WEEK_04.md","Week 4 · Day 23")
A25: 24 | B25: =START!$B$4+A25-1 | C25: =TEXT(B25,"ddd") | D25: 4 | E25: Foundations | F25: Prefix sums plus a frequency map | G25: Subarray Sum Equals K | H25: Delegates, lambdas, closures and events | I25: What does a closure allocate, and what is the loop-variable trap? | J25: Not started | M25: =HYPERLINK("WEEKS/WEEK_04.md","Week 4 · Day 24")
A26: 25 | B26: =START!$B$4+A26-1 | C26: =TEXT(B26,"ddd") | D26: 4 | E26: Foundations | F26: Local and global optimum (Kadane) | G26: Best Time to Buy and Sell Stock, Maximum Subarray | H26: Exceptions: throw vs throw ex, filters, cost, using and IDisposable basics | I26: What is the difference between throw and throw ex? | J26: Not started | M26: =HYPERLINK("WEEKS/WEEK_04.md","Week 4 · Day 25")
A27: 26 | B27: =START!$B$4+A27-1 | C27: =TEXT(B27,"ddd") | D27: 4 | E27: Foundations | F27: Repair and retrieval | G27: re-solves + Contains Duplicate II | H27: re-explain the week | J27: Not started | M27: =HYPERLINK("WEEKS/WEEK_04.md","Week 4 · Day 26")
A28: 27 | B28: =START!$B$4+A28-1 | C28: =TEXT(B28,"ddd") | D28: 4 | E28: Foundations | F28: Deep work: DSA + design + lab/project | G28: Product of Array Except Self, Longest Repeating Character Replacement, Permutation in String, Group Anagrams | H28: URL shortener — data model and key generation (base62 counter vs hash), a cache, and a request-rate estimate. Still one | J28: Not started | M28: =HYPERLINK("WEEKS/WEEK_04.md","Week 4 · Day 27")
A29: 28 | B29: =START!$B$4+A29-1 | C29: =TEXT(B29,"ddd") | D29: 4 | E29: Foundations | F29: Month 1 checkpoint | H29: Month 1 test (see checkpoint below). Then repair the weakest prerequisite you found. | J29: Not started | M29: =HYPERLINK("WEEKS/WEEK_04.md","Week 4 · Day 28")
A30: 29 | B30: =START!$B$4+A30-1 | C30: =TEXT(B30,"ddd") | D30: 5 | E30: Foundations | F30: Binary search invariant | G30: Binary Search, Search Insert Position | H30: IDisposable, using, the dispose pattern and finalizers | I30: Why does a finalizer make collection take (at least) two GC cycles? | J30: Not started | M30: =HYPERLINK("WEEKS/WEEK_05.md","Week 5 · Day 29")
A31: 30 | B31: =START!$B$4+A31-1 | C31: =TEXT(B31,"ddd") | D31: 5 | E31: Foundations | F31: Lower and upper bounds | G31: Find First and Last Position of Element in Sorted Array, First Bad Version | H31: GC generations, the large object heap, workstation vs server GC | I31: Why is a gen 0 collection cheap and a gen 2 collection expensive? | J31: Not started | M31: =HYPERLINK("WEEKS/WEEK_05.md","Week 5 · Day 30")
A32: 31 | B32: =START!$B$4+A32-1 | C32: =TEXT(B32,"ddd") | D32: 5 | E32: Foundations | F32: Rotated sorted arrays | G32: Find Minimum in Rotated Sorted Array, Search in Rotated Sorted Array | H32: async/await: what await does and the generated state machine | I32: What does await actually do? | J32: Not started | M32: =HYPERLINK("WEEKS/WEEK_05.md","Week 5 · Day 31")
A33: 32 | B33: =START!$B$4+A33-1 | C33: =TEXT(B33,"ddd") | D33: 5 | E33: Foundations | F33: Binary search on the answer | G33: Koko Eating Bananas, Capacity To Ship Packages Within D Days | H33: async pitfalls: async void, .Result deadlock, ConfigureAwait, ValueTask, CancellationToken | I33: Why does calling .Result deadlock in an app with a synchronization context? | J33: Not started | M33: =HYPERLINK("WEEKS/WEEK_05.md","Week 5 · Day 32")
A34: 33 | B34: =START!$B$4+A34-1 | C34: =TEXT(B34,"ddd") | D34: 5 | E34: Foundations | F34: Repair and retrieval | G34: re-solves + Sqrt(x) | H34: re-explain the week | J34: Not started | M34: =HYPERLINK("WEEKS/WEEK_05.md","Week 5 · Day 33")
A35: 34 | B35: =START!$B$4+A35-1 | C35: =TEXT(B35,"ddd") | D35: 5 | E35: Foundations | F35: Deep work: DSA + design + lab/project | G35: Implement merge sort (stable, O(n log n), O(n) extra), Implement quicksort partition (Lomuto and Hoare) and quickselect, Sort an Array, Sort Colors | H35: URL shortener — full 30-minute design: requirements, estimate, API, schema and indexes, cache, one failure (cache down). | J35: Not started | M35: =HYPERLINK("WEEKS/WEEK_05.md","Week 5 · Day 34")
A36: 35 | B36: =START!$B$4+A36-1 | C36: =TEXT(B36,"ddd") | D36: 5 | E36: Foundations | F36: Weekly test, review, project, stories | H36: Read Stephen Toub's 'How Async/Await Really Works in C#' (devblogs.microsoft.com) for 60 minutes; write a six-question s | J36: Not started | M36: =HYPERLINK("WEEKS/WEEK_05.md","Week 5 · Day 35")
A37: 36 | B37: =START!$B$4+A37-1 | C37: =TEXT(B37,"ddd") | D37: 6 | E37: Foundations | F37: Linked-list reference mutation | G37: Reverse Linked List, Middle of the Linked List | H37: OS vocabulary; process vs thread vs Task; the thread pool and starvation | I37: What is thread-pool starvation and how would you spot it? | J37: Not started | M37: =HYPERLINK("WEEKS/WEEK_06.md","Week 6 · Day 36")
A38: 37 | B38: =START!$B$4+A38-1 | C38: =TEXT(B38,"ddd") | D38: 6 | E38: Foundations | F38: Dummy node and merging | G38: Merge Two Sorted Lists, Remove Nth Node From End of List | H38: Race conditions, lock, Interlocked, volatile | I38: What is a race condition at the memory level? | J38: Not started | M38: =HYPERLINK("WEEKS/WEEK_06.md","Week 6 · Day 37")
A39: 38 | B39: =START!$B$4+A39-1 | C39: =TEXT(B39,"ddd") | D39: 6 | E39: Foundations | F39: Cycles and palindromes | G39: Linked List Cycle, Palindrome Linked List | H39: Deadlock, why not await inside lock, SemaphoreSlim vs Mutex vs ReaderWriterLockSlim | I39: What causes a deadlock and how do you prevent one? | J39: Not started | M39: =HYPERLINK("WEEKS/WEEK_06.md","Week 6 · Day 38")
A40: 39 | B40: =START!$B$4+A40-1 | C40: =TEXT(B40,"ddd") | D40: 6 | E40: Foundations | F40: Stack and queue contracts | G40: Valid Parentheses, Implement Queue using Stacks | H40: Channel<T>, Parallel.For/PLINQ; your email pipeline as a concurrency story | I40: When does Parallel.For hurt rather than help? | J40: Not started | M40: =HYPERLINK("WEEKS/WEEK_06.md","Week 6 · Day 39")
...

Sheet DSA_LOG
A1: Planned day | B1: Problem | C1: Difficulty | D1: Pattern | E1: Result | F1: Solved on | G1: Brute force | H1: Insight (one sentence) | I1: Invariant | J1: Time / space | K1: One variation | L1: Re-solve D+1 | M1: D+3 | N1: D+7 | O1: D+14 | P1: Re-solve results
A2: 1 | B2: =HYPERLINK("PROBLEMS.md#x-array-basics","Array basics: print, sum, max, min, count of a target (handle empty input)") | C2: Custom | D2: Arrays | E2: Not started | L2: =IF(F2="","",F2+1) | M2: =IF(F2="","",F2+3) | N2: =IF(F2="","",F2+7) | O2: =IF(F2="","",F2+14)
A3: 2 | B3: =HYPERLINK("PROBLEMS.md#x-linear-search","Linear search, first/last occurrence, minimum/maximum with index") | C3: Custom | D3: Arrays | E3: Not started | L3: =IF(F3="","",F3+1) | M3: =IF(F3="","",F3+3) | N3: =IF(F3="","",F3+7) | O3: =IF(F3="","",F3+14)
A4: 3 | B4: =HYPERLINK("PROBLEMS.md#x-reverse","Reverse an array in place with two indexes (0, 1, odd, even lengths)") | C4: Custom | D4: Arrays | E4: Not started | L4: =IF(F4="","",F4+1) | M4: =IF(F4="","",F4+3) | N4: =IF(F4="","",F4+7) | O4: =IF(F4="","",F4+14)
A5: 4 | B5: =HYPERLINK("PROBLEMS.md#x-sorted-second","Check sorted order; second-largest DISTINCT value") | C5: Custom | D5: Arrays | E5: Not started | L5: =IF(F5="","",F5+1) | M5: =IF(F5="","",F5+3) | N5: =IF(F5="","",F5+7) | O5: =IF(F5="","",F5+14)
A6: 5 | B6: =HYPERLINK("https://leetcode.com/problems/concatenation-of-array/","Concatenation of Array (1929)") | C6: Easy | D6: Arrays | E6: Not started | L6: =IF(F6="","",F6+1) | M6: =IF(F6="","",F6+3) | N6: =IF(F6="","",F6+7) | O6: =IF(F6="","",F6+14)
A7: 5 | B7: =HYPERLINK("https://leetcode.com/problems/detect-squares/","Detect Squares (2013)") | C7: Medium | D7: Hashing | E7: Not started | L7: =IF(F7="","",F7+1) | M7: =IF(F7="","",F7+3) | N7: =IF(F7="","",F7+7) | O7: =IF(F7="","",F7+14)
A8: 6 | B8: =HYPERLINK("https://leetcode.com/problems/contains-duplicate/","Contains Duplicate (217)") | C8: Easy | D8: Hashing | E8: Not started | L8: =IF(F8="","",F8+1) | M8: =IF(F8="","",F8+3) | N8: =IF(F8="","",F8+7) | O8: =IF(F8="","",F8+14)
A9: 6 | B9: =HYPERLINK("PROBLEMS.md#x-insert-delete","Insert / delete at an index by shifting, with spare capacity") | C9: Custom | D9: Arrays | E9: Not started | L9: =IF(F9="","",F9+1) | M9: =IF(F9="","",F9+3) | N9: =IF(F9="","",F9+7) | O9: =IF(F9="","",F9+14)
A10: 8 | B10: =HYPERLINK("PROBLEMS.md#x-frequency","Frequency map of an int[] with Dictionary (TryGetValue)") | C10: Custom | D10: Hashing | E10: Not started | L10: =IF(F10="","",F10+1) | M10: =IF(F10="","",F10+3) | N10: =IF(F10="","",F10+7) | O10: =IF(F10="","",F10+14)
A11: 9 | B11: =HYPERLINK("https://leetcode.com/problems/two-sum/","Two Sum (1)") | C11: Easy | D11: Hashing | E11: Not started | L11: =IF(F11="","",F11+1) | M11: =IF(F11="","",F11+3) | N11: =IF(F11="","",F11+7) | O11: =IF(F11="","",F11+14)
A12: 10 | B12: =HYPERLINK("https://leetcode.com/problems/longest-consecutive-sequence/","Longest Consecutive Sequence (128)") | C12: Medium | D12: Hashing | E12: Not started | L12: =IF(F12="","",F12+1) | M12: =IF(F12="","",F12+3) | N12: =IF(F12="","",F12+7) | O12: =IF(F12="","",F12+14)
A13: 11 | B13: =HYPERLINK("https://leetcode.com/problems/remove-element/","Remove Element (27)") | C13: Easy | D13: Two pointers | E13: Not started | L13: =IF(F13="","",F13+1) | M13: =IF(F13="","",F13+3) | N13: =IF(F13="","",F13+7) | O13: =IF(F13="","",F13+14)
A14: 11 | B14: =HYPERLINK("https://leetcode.com/problems/move-zeroes/","Move Zeroes (283)") | C14: Easy | D14: Two pointers | E14: Not started | L14: =IF(F14="","",F14+1) | M14: =IF(F14="","",F14+3) | N14: =IF(F14="","",F14+7) | O14: =IF(F14="","",F14+14)
A15: 12 | B15: =HYPERLINK("https://leetcode.com/problems/range-sum-query-2d-immutable/","Range Sum Query 2D - Immutable (304)") | C15: Medium | D15: Prefix sum | E15: Not started | L15: =IF(F15="","",F15+1) | M15: =IF(F15="","",F15+3) | N15: =IF(F15="","",F15+7) | O15: =IF(F15="","",F15+14)
A16: 12 | B16: =HYPERLINK("https://leetcode.com/problems/find-all-numbers-disappeared-in-an-array/","Find All Numbers Disappeared in an Array (448)") | C16: Easy | D16: Arrays | E16: Not started | L16: =IF(F16="","",F16+1) | M16: =IF(F16="","",F16+3) | N16: =IF(F16="","",F16+7) | O16: =IF(F16="","",F16+14)
A17: 13 | B17: =HYPERLINK("https://leetcode.com/problems/running-sum-of-1d-array/","Running Sum of 1d Array (1480)") | C17: Easy | D17: Prefix sum | E17: Not started | L17: =IF(F17="","",F17+1) | M17: =IF(F17="","",F17+3) | N17: =IF(F17="","",F17+7) | O17: =IF(F17="","",F17+14)
A18: 13 | B18: =HYPERLINK("https://leetcode.com/problems/remove-duplicates-from-sorted-array/","Remove Duplicates from Sorted Array (26)") | C18: Easy | D18: Two pointers | E18: Not started | L18: =IF(F18="","",F18+1) | M18: =IF(F18="","",F18+3) | N18: =IF(F18="","",F18+7) | O18: =IF(F18="","",F18+14)
A19: 13 | B19: =HYPERLINK("https://leetcode.com/problems/range-sum-query-immutable/","Range Sum Query - Immutable (303)") | C19: Easy | D19: Prefix sum | E19: Not started | L19: =IF(F19="","",F19+1) | M19: =IF(F19="","",F19+3) | N19: =IF(F19="","",F19+7) | O19: =IF(F19="","",F19+14)
A20: 13 | B20: =HYPERLINK("https://leetcode.com/problems/plus-one/","Plus One (66)") | C20: Easy | D20: Arrays | E20: Not started | L20: =IF(F20="","",F20+1) | M20: =IF(F20="","",F20+3) | N20: =IF(F20="","",F20+7) | O20: =IF(F20="","",F20+14)
A21: 13 | B21: =HYPERLINK("https://leetcode.com/problems/merge-sorted-array/","Merge Sorted Array (88)") | C21: Easy | D21: Two pointers | E21: Not started | L21: =IF(F21="","",F21+1) | M21: =IF(F21="","",F21+3) | N21: =IF(F21="","",F21+7) | O21: =IF(F21="","",F21+14)
A22: 15 | B22: =HYPERLINK("https://leetcode.com/problems/valid-anagram/","Valid Anagram (242)") | C22: Easy | D22: Strings | E22: Not started | L22: =IF(F22="","",F22+1) | M22: =IF(F22="","",F22+3) | N22: =IF(F22="","",F22+7) | O22: =IF(F22="","",F22+14)
A23: 15 | B23: =HYPERLINK("https://leetcode.com/problems/ransom-note/","Ransom Note (383)") | C23: Easy | D23: Strings | E23: Not started | L23: =IF(F23="","",F23+1) | M23: =IF(F23="","",F23+3) | N23: =IF(F23="","",F23+7) | O23: =IF(F23="","",F23+14)
A24: 16 | B24: =HYPERLINK("https://leetcode.com/problems/valid-palindrome/","Valid Palindrome (125)") | C24: Easy | D24: Two pointers | E24: Not started | L24: =IF(F24="","",F24+1) | M24: =IF(F24="","",F24+3) | N24: =IF(F24="","",F24+7) | O24: =IF(F24="","",F24+14)
A25: 16 | B25: =HYPERLINK("https://leetcode.com/problems/valid-palindrome-ii/","Valid Palindrome II (680)") | C25: Easy | D25: Two pointers | E25: Not started | L25: =IF(F25="","",F25+1) | M25: =IF(F25="","",F25+3) | N25: =IF(F25="","",F25+7) | O25: =IF(F25="","",F25+14)
A26: 17 | B26: =HYPERLINK("https://leetcode.com/problems/two-sum-ii-input-array-is-sorted/","Two Sum II - Input Array Is Sorted (167)") | C26: Medium | D26: Two pointers | E26: Not started | L26: =IF(F26="","",F26+1) | M26: =IF(F26="","",F26+3) | N26: =IF(F26="","",F26+7) | O26: =IF(F26="","",F26+14)
A27: 17 | B27: =HYPERLINK("https://leetcode.com/problems/squares-of-a-sorted-array/","Squares of a Sorted Array (977)") | C27: Easy | D27: Two pointers | E27: Not started | L27: =IF(F27="","",F27+1) | M27: =IF(F27="","",F27+3) | N27: =IF(F27="","",F27+7) | O27: =IF(F27="","",F27+14)
A28: 18 | B28: =HYPERLINK("https://leetcode.com/problems/longest-common-prefix/","Longest Common Prefix (14)") | C28: Easy | D28: Strings | E28: Not started | L28: =IF(F28="","",F28+1) | M28: =IF(F28="","",F28+3) | N28: =IF(F28="","",F28+7) | O28: =IF(F28="","",F28+14)
A29: 18 | B29: =HYPERLINK("https://leetcode.com/problems/maximum-average-subarray-i/","Maximum Average Subarray I (643)") | C29: Easy | D29: Sliding window | E29: Not started | L29: =IF(F29="","",F29+1) | M29: =IF(F29="","",F29+3) | N29: =IF(F29="","",F29+7) | O29: =IF(F29="","",F29+14)
A30: 19 | B30: =HYPERLINK("https://leetcode.com/problems/encode-and-decode-strings/","Encode and Decode Strings (271)") | C30: Medium | D30: Strings | E30: Not started | L30: =IF(F30="","",F30+1) | M30: =IF(F30="","",F30+3) | N30: =IF(F30="","",F30+7) | O30: =IF(F30="","",F30+14)
A31: 19 | B31: =HYPERLINK("https://leetcode.com/problems/reverse-string/","Reverse String (344)") | C31: Easy | D31: Two pointers | E31: Not started | L31: =IF(F31="","",F31+1) | M31: =IF(F31="","",F31+3) | N31: =IF(F31="","",F31+7) | O31: =IF(F31="","",F31+14)
A32: 20 | B32: =HYPERLINK("https://leetcode.com/problems/3sum/","3Sum (15)") | C32: Medium | D32: Two pointers | E32: Not started | L32: =IF(F32="","",F32+1) | M32: =IF(F32="","",F32+3) | N32: =IF(F32="","",F32+7) | O32: =IF(F32="","",F32+14)
A33: 20 | B33: =HYPERLINK("https://leetcode.com/problems/isomorphic-strings/","Isomorphic Strings (205)") | C33: Easy | D33: Strings | E33: Not started | L33: =IF(F33="","",F33+1) | M33: =IF(F33="","",F33+3) | N33: =IF(F33="","",F33+7) | O33: =IF(F33="","",F33+14)
A34: 20 | B34: =HYPERLINK("https://leetcode.com/problems/word-pattern/","Word Pattern (290)") | C34: Easy | D34: Strings | E34: Not started | L34: =IF(F34="","",F34+1) | M34: =IF(F34="","",F34+3) | N34: =IF(F34="","",F34+7) | O34: =IF(F34="","",F34+14)
A35: 20 | B35: =HYPERLINK("https://leetcode.com/problems/first-unique-character-in-a-string/","First Unique Character in a String (387)") | C35: Easy | D35: Strings | E35: Not started | L35: =IF(F35="","",F35+1) | M35: =IF(F35="","",F35+3) | N35: =IF(F35="","",F35+7) | O35: =IF(F35="","",F35+14)
A36: 22 | B36: =HYPERLINK("https://leetcode.com/problems/longest-substring-without-repeating-characters/","Longest Substring Without Repeating Characters (3)") | C36: Medium | D36: Sliding window | E36: Not started | L36: =IF(F36="","",F36+1) | M36: =IF(F36="","",F36+3) | N36: =IF(F36="","",F36+7) | O36: =IF(F36="","",F36+14)
A37: 23 | B37: =HYPERLINK("https://leetcode.com/problems/max-consecutive-ones-iii/","Max Consecutive Ones III (1004)") | C37: Medium | D37: Sliding window | E37: Not started | L37: =IF(F37="","",F37+1) | M37: =IF(F37="","",F37+3) | N37: =IF(F37="","",F37+7) | O37: =IF(F37="","",F37+14)
A38: 23 | B38: =HYPERLINK("https://leetcode.com/problems/minimum-size-subarray-sum/","Minimum Size Subarray Sum (209)") | C38: Medium | D38: Sliding window | E38: Not started | L38: =IF(F38="","",F38+1) | M38: =IF(F38="","",F38+3) | N38: =IF(F38="","",F38+7) | O38: =IF(F38="","",F38+14)
A39: 24 | B39: =HYPERLINK("https://leetcode.com/problems/subarray-sum-equals-k/","Subarray Sum Equals K (560)") | C39: Medium | D39: Prefix sum | E39: Not started | L39: =IF(F39="","",F39+1) | M39: =IF(F39="","",F39+3) | N39: =IF(F39="","",F39+7) | O39: =IF(F39="","",F39+14)
A40: 25 | B40: =HYPERLINK("https://leetcode.com/problems/best-time-to-buy-and-sell-stock/","Best Time to Buy and Sell Stock (121)") | C40: Easy | D40: Arrays | E40: Not started | L40: =IF(F40="","",F40+1) | M40: =IF(F40="","",F40+3) | N40: =IF(F40="","",F40+7) | O40: =IF(F40="","",F40+14)
...

Sheet REVIEW
A1: Planned day | B1: Concept (explain aloud) | C1: Learned on | D1: D+1 | E1: D+3 | F1: D+7 | G1: D+14 | H1: D+30 | I1: Last result
A2: 1 | B2: Why is reading a[i] O(1) but finding a value O(n)? | D2: =IF(C2="","",C2+1) | E2: =IF(C2="","",C2+3) | F2: =IF(C2="","",C2+7) | G2: =IF(C2="","",C2+14) | H2: =IF(C2="","",C2+30)
A3: 2 | B3: What is overflow and when should a sum use long? | D3: =IF(C3="","",C3+1) | E3: =IF(C3="","",C3+3) | F3: =IF(C3="","",C3+7) | G3: =IF(C3="","",C3+14) | H3: =IF(C3="","",C3+30)
A4: 3 | B4: What does a variable of a value type hold, and what does a reference-type variable hold? | D4: =IF(C4="","",C4+1) | E4: =IF(C4="","",C4+3) | F4: =IF(C4="","",C4+7) | G4: =IF(C4="","",C4+14) | H4: =IF(C4="","",C4+30)
A5: 4 | B5: Where does a struct live — the stack or the heap? (It depends on where it is declared.) | D5: =IF(C5="","",C5+1) | E5: =IF(C5="","",C5+3) | F5: =IF(C5="","",C5+7) | G5: =IF(C5="","",C5+14) | H5: =IF(C5="","",C5+30)
A6: 8 | B6: What is boxing, what does it cost, and name three places it happens by accident. | D6: =IF(C6="","",C6+1) | E6: =IF(C6="","",C6+3) | F6: =IF(C6="","",C6+7) | G6: =IF(C6="","",C6+14) | H6: =IF(C6="","",C6+30)
A7: 9 | B7: State the Equals/GetHashCode contract and what breaks without it. | D7: =IF(C7="","",C7+1) | E7: =IF(C7="","",C7+3) | F7: =IF(C7="","",C7+7) | G7: =IF(C7="","",C7+14) | H7: =IF(C7="","",C7+30)
A8: 10 | B8: Why is Dictionary lookup O(1) on average, and what makes it O(n)? | D8: =IF(C8="","",C8+1) | E8: =IF(C8="","",C8+3) | F8: =IF(C8="","",C8+7) | G8: =IF(C8="","",C8+14) | H8: =IF(C8="","",C8+30)
A9: 11 | B9: Explain ref, out and in in one sentence each. | D9: =IF(C9="","",C9+1) | E9: =IF(C9="","",C9+3) | F9: =IF(C9="","",C9+7) | G9: =IF(C9="","",C9+14) | H9: =IF(C9="","",C9+30)
A10: 15 | B10: Why is string concatenation in a loop O(n²)? | D10: =IF(C10="","",C10+1) | E10: =IF(C10="","",C10+3) | F10: =IF(C10="","",C10+7) | G10: =IF(C10="","",C10+14) | H10: =IF(C10="","",C10+30)
A11: 16 | B11: What is the job of a constructor? | D11: =IF(C11="","",C11+1) | E11: =IF(C11="","",C11+3) | F11: =IF(C11="","",C11+7) | G11: =IF(C11="","",C11+14) | H11: =IF(C11="","",C11+30)
A12: 17 | B12: Interface or abstract class — how do you decide? | D12: =IF(C12="","",C12+1) | E12: =IF(C12="","",C12+3) | F12: =IF(C12="","",C12+7) | G12: =IF(C12="","",C12+14) | H12: =IF(C12="","",C12+30)
A13: 18 | B13: Why composition over inheritance? | D13: =IF(C13="","",C13+1) | E13: =IF(C13="","",C13+3) | F13: =IF(C13="","",C13+7) | G13: =IF(C13="","",C13+14) | H13: =IF(C13="","",C13+30)
... A129: 221 | B129: What did these eight months change in how you engineer? | D129: =IF(C129="","",C129+1) | E129: =IF(C129="","",C129+3) | F129: =IF(C129="","",C129+7) | G129: =IF(C129="","",C129+14) | H129: =IF(C129="","",C129+30)

Sheet WEAK
A1: Item | B1: Added on | C1: Where it came from | D1: Try 1 | E1: Try 2 | F1: Cleared on | G1: Note

Sheet DESIGNS
A1: ID | B1: Type | C1: Design | D1: Planned day(s) | E1: Done on | F1: Minutes | G1: Score /20 | H1: What I missed | I1: Redo on
A2: url-shortener | B2: HLD | C2: =HYPERLINK("DESIGNS.md#hld-url-shortener","URL shortener (TinyURL)") | D2: 20, 27, 34, 55, 202
A3: pastebin | B3: HLD | C3: =HYPERLINK("DESIGNS.md#hld-pastebin","Pastebin") | D3: 117
A4: rate-limiter | B4: HLD | C4: =HYPERLINK("DESIGNS.md#hld-rate-limiter","Distributed rate limiter") | D4: 69, 202
A5: notification | B5: HLD | C5: =HYPERLINK("DESIGNS.md#hld-notification","Notification service (email/SMS/push)") | D5: 83, 146, 202
A6: job-platform | B6: HLD | C6: =HYPERLINK("DESIGNS.md#hld-job-platform","Distributed job scheduler / task queue (your project)") | D6: 76, 167, 216
A7: dropbox | B7: HLD | C7: =HYPERLINK("DESIGNS.md#hld-dropbox","File storage and sync (Dropbox / Google Drive)") | D7: 195
A8: news-feed | B8: HLD | C8: =HYPERLINK("DESIGNS.md#hld-news-feed","News feed (Facebook / Twitter timeline)") | D8: 125, 209
A9: ecommerce | B9: HLD | C9: =HYPERLINK("DESIGNS.md#hld-ecommerce","E-commerce checkout, orders and inventory (Amazon)") | D9: 139
A10: payment | B10: HLD | C10: =HYPERLINK("DESIGNS.md#hld-payment","Payment system / wallet (PhonePe)") | D10: 139, 216
A11: chat | B11: HLD | C11: =HYPERLINK("DESIGNS.md#hld-chat","Chat and messaging (WhatsApp / Slack)") | D11: 118, 209
A12: web-crawler | B12: HLD | C12: =HYPERLINK("DESIGNS.md#hld-web-crawler","Web crawler") | D12: 143
A13: youtube | B13: HLD | C13: =HYPERLINK("DESIGNS.md#hld-youtube","Video upload and streaming (YouTube)") | D13: 150, 199
A14: typeahead | B14: HLD | C14: =HYPERLINK("DESIGNS.md#hld-typeahead","Search autocomplete / typeahead") | D14: 150, 199
A15: google-docs | B15: HLD | C15: =HYPERLINK("DESIGNS.md#hld-google-docs","Collaborative editor (Google Docs)") | D15: 164
A16: distributed-cache | B16: HLD | C16: =HYPERLINK("DESIGNS.md#hld-distributed-cache","Distributed cache (Redis-like)") | D16: 165
A17: ad-click-aggregation | B17: HLD | C17: =HYPERLINK("DESIGNS.md#hld-ad-click-aggregation","Ad-click aggregation (stream processing)") | D17: 174
A18: metrics-monitoring | B18: HLD | C18: =HYPERLINK("DESIGNS.md#hld-metrics-monitoring","Metrics and monitoring system") | D18: 181
A19: proximity | B19: HLD | C19: =HYPERLINK("DESIGNS.md#hld-proximity","Proximity / nearby search (Yelp, Google Maps nearby)") | D19: 188, 199
A20: object-storage | B20: HLD | C20: =HYPERLINK("DESIGNS.md#hld-object-storage","Object storage (S3-like)") | D20: 195
A21: uber | B21: HLD | C21: =HYPERLINK("DESIGNS.md#hld-uber","Ride sharing and matching (Uber)") | D21: 188
A22: hotel-booking | B22: HLD | C22: =HYPERLINK("DESIGNS.md#hld-hotel-booking","Hotel booking (Booking.com)") | D22: 132, 216
A23: ticket-booking | B23: HLD | C23: =HYPERLINK("DESIGNS.md#hld-ticket-booking","Movie / event ticket booking (BookMyShow)") | D23: 132
A24: flight-booking | B24: HLD | C24: =HYPERLINK("DESIGNS.md#hld-flight-booking","Flight booking") | D24: 119
A25: restaurant-reservation | B25: HLD | C25: =HYPERLINK("DESIGNS.md#hld-restaurant-reservation","Restaurant reservation") | D25: 124
A26: food-delivery | B26: HLD | C26: =HYPERLINK("DESIGNS.md#hld-food-delivery","Food delivery (Swiggy / Zomato)") | D26: 126
A27: logging-pipeline | B27: HLD | C27: =HYPERLINK("DESIGNS.md#hld-logging-pipeline","Logging pipeline") | D27: 131
A28: email-delivery | B28: HLD | C28: =HYPERLINK("DESIGNS.md#hld-email-delivery","Email delivery service") | D28: 133
A29: instagram | B29: HLD | C29: =HYPERLINK("DESIGNS.md#hld-instagram","Photo sharing (Instagram)") | D29: 138
A30: tiktok | B30: HLD | C30: =HYPERLINK("DESIGNS.md#hld-tiktok","Short-video feed (TikTok)") | D30: 140
A31: pinterest | B31: HLD | C31: =HYPERLINK("DESIGNS.md#hld-pinterest","Pinterest") | D31: 145
A32: reddit | B32: HLD | C32: =HYPERLINK("DESIGNS.md#hld-reddit","Community discussion and voting (Reddit)") | D32: 147
A33: netflix | B33: HLD | C33: =HYPERLINK("DESIGNS.md#hld-netflix","Video-on-demand streaming (Netflix)") | D33: 152
A34: spotify | B34: HLD | C34: =HYPERLINK("DESIGNS.md#hld-spotify","Music streaming (Spotify)") | D34: 154
A35: trending-topics | B35: HLD | C35: =HYPERLINK("DESIGNS.md#hld-trending-topics","Trending topics / top-K heavy hitters") | D35: 159
A36: cdn | B36: HLD | C36: =HYPERLINK("DESIGNS.md#hld-cdn","Content delivery network (CDN)") | D36: 161
A37: ad-serving | B37: HLD | C37: =HYPERLINK("DESIGNS.md#hld-ad-serving","Ad serving") | D37: 166
A38: recommendations | B38: HLD | C38: =HYPERLINK("DESIGNS.md#hld-recommendations","Recommendation system") | D38: 168
A39: leaderboard | B39: HLD | C39: =HYPERLINK("DESIGNS.md#hld-leaderboard","Real-time leaderboard") | D39: 173
A40: multi-region | B40: HLD | C40: =HYPERLINK("DESIGNS.md#hld-multi-region","Multi-region evolution of an earlier design") | D40: 181
...

Sheet STORIES
A1: Story (real only) | B1: From | C1: Worksheet | D1: Recorded | E1: Customer Obsession | F1: Ownership | G1: Invent and Simplify | H1: Are Right, A Lot | I1: Learn and Be Curious | J1: Hire and Develop the Best | K1: Insist on the Highest Standards | L1: Think Big | M1: Bias for Action | N1: Frugality | O1: Earn Trust | P1: Dive Deep | Q1: Have Backbone; Disagree and Commit | R1: Deliver Results | S1: Strive to be Earth's Best Employer | T1: Success and Scale Bring Broad Responsibility
A2: Email pipeline: 7–10 h → about 1–1.5 h (flagship) | B2: Casepoint | C2: No | D2: No
A3: Embedding eligibility counts: 11 queries → 2 set-based | B3: Casepoint | C3: No | D3: No
A4: FOIA / regulated disclosure workflows | B4: Casepoint | C4: No | D4: No
A5: Legacy code: tracing paths before changing | B5: Casepoint | C5: No | D5: No
A6: SQL / index tuning on eDiscovery data | B6: Casepoint | C6: No | D6: No
A7: Multilingual processing | B7: Casepoint | C7: No | D7: No
A8: Production incident resolution | B8: Vision Infotech | C8: No | D8: No
A9: Client modules end to end | B9: Vision Infotech | C9: No | D9: No
A10: SignalR + FCM messaging (VCDoctor) | B10: Vision Infotech | C10: No | D10: No
A11: Payments: Stripe / PayPal / CCAvenue | B11: Vision / Zibma | C11: No | D11: No
A12: Vonage video (VCDoctor) | B12: Vision Infotech | C12: No | D12: No
A13: 100k+ record performance (ERP) | B13: Zibma Infotech | C13: No | D13: No
A14: ERP reporting / .NET Core APIs into ASP.NET | B14: Zibma Infotech | C14: No | D14: No
A15: Disagreement with a senior — FIND A REAL ONE | C15: No | D15: No
A16: Hard feedback / I was wrong — FIND A REAL ONE | C16: No | D16: No
A17: Helping a junior — only if real | C17: No | D17: No
A18: The job platform project — only after it is built | B18: Study project | C18: No | D18: No

Sheet JOURNAL
A1: Date | B1: One line: problem, decision, outcome | C1: Story candidate?

Sheet PROJECT
A1: Milestone | B1: Week | C1: Build | D1: Acceptance test | E1: Status | F1: Evidence (link / note)
A2: M1 | B2: 11 | C2: Small API, durable metadata, state machine | D2: Job readable after restart; illegal transition rejected | E2: Not started
A3: M2 | B3: 12 | C3: RabbitMQ + worker, attempt history, graceful shutdown | D3: Stopped worker → message redelivered, job finishes | E3: Not started
A4: M3 | B4: 13 | C4: Transactional outbox + relay | D4: Crash between commit and publish → job still delivered | E4: Not started
A5: M4 | B5: 14 | C5: Idempotent consumption and submission | D5: Duplicate delivery → one effect; duplicate POST → same response | E5: Not started
A6: M5 | B6: 15 | C6: Security | D6: 10 security tests pass, incl. cross-tenant 404 | E6: Not started
A7: M6 | B7: 16 | C7: Docker Compose + CI | D7: Clean clone runs; failing test blocks merge | E7: Not started
A8: M7 | B8: 17 | C8: Retries, DLQ/replay, leases/reaper, cancellation | D8: Kill worker mid-job → completes; poison → DLQ → replay | E8: Not started
A9: M8 | B9: 18 | C9: Fairness, observability, deployment | D9: Noisy tenant cannot starve; one job traced end to end | E9: Not started
A10: M9 | B10: 19 | C10: Load tests, failure tests, restore | D10: Benchmark report complete; restore verified | E10: Not started
A11: M10 | B11: 20 | C11: README, decisions, defense, scope freeze | D11: 15-minute defense recorded | E11: Not started
A12: M11 | B12: 25–28 | C12: AI increment (indexing, retrieval, evaluation, optional MCP) | D12: Measured recall@k; negative security tests | E12: Not started
A13: M12 | B13: 29 | C13: Optional: Kubernetes/KEDA or SQS port | D13: Runs, with a written limitation | E13: Not started

Sheet APPLY
A1: Company | B1: Country | C1: Route / note | D1: Tier | E1: On sponsor register? | F1: LinkedIn test | G1: Applied on | H1: Referral | I1: Stage | J1: Next action | K1: By when
A2: Thomson Reuters | B2: Canada | C2: Seeded Aug 2026 — verify route first | D2: 3A
A3: OpenText | B3: Canada | C3: Seeded Aug 2026 — verify | D3: 3A
A4: Magnet Forensics | B4: Canada | C4: Sponsorship unverified | D4: 3A
A5: Constellation Software | B5: Canada | C5: Seeded — verify | D5: 3A
A6: Xero | B6: New Zealand | C6: Seeded — verify | D6: 3B
A7: Datacom | B7: New Zealand | C7: Seeded — verify | D7: 3B
A8: Nuix | B8: Australia | C8: Stack may be Java-leaning — verify | D8: 3C
A9: Objective Corp | B9: Australia | C9: Seeded — verify | D9: 3C
A10: WiseTech | B10: Australia | C10: Seeded — verify | D10: 3C
A11: Microsoft Dublin | B11: Ireland | C11: Ireland gated on NFQ check | D11: 3E
A12: Fidelity | B12: Ireland | C12: Ireland gated on NFQ check | D12: 3E
A13: Version 1 | B13: Ireland | C13: Ireland gated on NFQ check | D13: 3E
... A18: Casepoint US (L-1 transfer) | B18: USA | C18: CLOSED — employer offers no overseas transfer | D18: struck

Sheet INTERVIEWS
A1: Company | B1: Round | C1: Date | D1: Questions asked (verbatim) | E1: What went well | F1: What went badly (exact moment) | G1: Root cause | H1: Repair action | I1: Repair by

Sheet DASHBOARD
A1: Measure | B1: Value
A2: Days done (of 224) | B2: =COUNTIF(DAILY!J2:J225,"Done")
A3: Share of days done | B3: =COUNTIF(DAILY!J2:J225,"Done")/224
A4: Problems solved independently | B4: =COUNTIF(DSA_LOG!E2:E2000,"Independent")
A5: Problems with a hint | B5: =COUNTIF(DSA_LOG!E2:E2000,"Hint")
A6: Problems failed / solution read | B6: =COUNTIF(DSA_LOG!E2:E2000,"Failed")+COUNTIF(DSA_LOG!E2:E2000,"Solution read")
A7: Concepts passing their last review | B7: =COUNTIF(REVIEW!I2:I400,"Pass")
A8: Weak items still open | B8: =COUNTA(WEAK!A2:A1000)-COUNTA(WEAK!F2:F1000)
A9: Designs done | B9: =COUNTA(DESIGNS!E2:E200)
A10: Stories recorded | B10: =COUNTIF(STORIES!D2:D60,"Yes")
A11: Journal lines | B11: =COUNTA(JOURNAL!A2:A2000)
A12: Project milestones done | B12: =COUNTIF(PROJECT!E2:E20,"Done")
A13: Applications sent | B13: =COUNTA(APPLY!G2:G500)
A14: Interviews analysed | B14: =COUNTA(INTERVIEWS!A2:A500)
